nohup: ignoring input
/home/jovyan/conda-envs/czl/lib/python3.9/site-packages/torch/distributed/launch.py:178: FutureWarning: The module torch.distributed.launch is deprecated
and will be removed in future. Use torchrun.
Note that --use_env is set by default in torchrun.
If your script expects `--local_rank` argument to be set, please
change it to read from `os.environ['LOCAL_RANK']` instead. See 
https://pytorch.org/docs/stable/distributed.html#launch-utility for 
further instructions

  warnings.warn(
WARNING:torch.distributed.run:
*****************************************
Setting OMP_NUM_THREADS environment variable for each process to be 1 in default, to avoid your system being overloaded, please further tune the variable for optimal performance in your application as needed. 
*****************************************
/home/jovyan/conda-envs/czl/lib/python3.9/site-packages/scipy/__init__.py:146: UserWarning: A NumPy version >=1.16.5 and <1.23.0 is required for this version of SciPy (detected version 1.23.1
  warnings.warn(f"A NumPy version >={np_minversion} and <{np_maxversion}"
/home/jovyan/conda-envs/czl/lib/python3.9/site-packages/scipy/__init__.py:146: UserWarning: A NumPy version >=1.16.5 and <1.23.0 is required for this version of SciPy (detected version 1.23.1
  warnings.warn(f"A NumPy version >={np_minversion} and <{np_maxversion}"
/home/jovyan/conda-envs/czl/lib/python3.9/site-packages/scipy/__init__.py:146: UserWarning: A NumPy version >=1.16.5 and <1.23.0 is required for this version of SciPy (detected version 1.23.1
  warnings.warn(f"A NumPy version >={np_minversion} and <{np_maxversion}"
/home/jovyan/conda-envs/czl/lib/python3.9/site-packages/scipy/__init__.py:146: UserWarning: A NumPy version >=1.16.5 and <1.23.0 is required for this version of SciPy (detected version 1.23.1
  warnings.warn(f"A NumPy version >={np_minversion} and <{np_maxversion}"
INFO:root:********************************************************
INFO:root:****************** Experiment setting ******************
INFO:root:label_train dir --------- ./data/json_update/avqa-train.json
INFO:root:label_val dir ----------- ./data/json_update/avqa-val.json
INFO:root:label_test dir ---------- ./data/json_update/avqa-test.json
INFO:root:audio dir --------------- ./data/feats/vggish
INFO:root:posi_video dir ---------- /data/avst/r2plus1d_18/
INFO:root:nega_video dir ---------- /data/avst/r2plus1d_18/
INFO:root:batch size -------------- 32
INFO:root:num of epoches ---------- 15
INFO:root:learning rate ----------- 0.0001
INFO:root:name of model ----------- AVQA_Fusion_Net
INFO:root:train or test ----------- test
INFO:root:model save dir ---------- ./data/checkpoints/checkpoint_no_MAM
INFO:root:num of dataloader workers 2
INFO:root:gpu id ------------------ 0
INFO:root:********************************************************
INFO:torch.distributed.distributed_c10d:Added key: store_based_barrier_key:1 to store for rank: 0
Traceback (most recent call last):
  File "/home/jovyan/Bert/main_avst_loc_glo.py", line 353, in <module>
Traceback (most recent call last):
  File "/home/jovyan/Bert/main_avst_loc_glo.py", line 353, in <module>
Traceback (most recent call last):
  File "/home/jovyan/Bert/main_avst_loc_glo.py", line 353, in <module>
    torch.cuda.set_device(args.local_rank)
  File "/home/jovyan/conda-envs/czl/lib/python3.9/site-packages/torch/cuda/__init__.py", line 314, in set_device
    torch.cuda.set_device(args.local_rank)
  File "/home/jovyan/conda-envs/czl/lib/python3.9/site-packages/torch/cuda/__init__.py", line 314, in set_device
    torch._C._cuda_setDevice(device)
RuntimeError: CUDA error: invalid device ordinal
CUDA kernel errors might be asynchronously reported at some other API call,so the stacktrace below might be incorrect.
For debugging consider passing CUDA_LAUNCH_BLOCKING=1.
    torch._C._cuda_setDevice(device)
RuntimeError: CUDA error: invalid device ordinal
CUDA kernel errors might be asynchronously reported at some other API call,so the stacktrace below might be incorrect.
For debugging consider passing CUDA_LAUNCH_BLOCKING=1.
    torch.cuda.set_device(args.local_rank)
  File "/home/jovyan/conda-envs/czl/lib/python3.9/site-packages/torch/cuda/__init__.py", line 314, in set_device
    torch._C._cuda_setDevice(device)
RuntimeError: CUDA error: invalid device ordinal
CUDA kernel errors might be asynchronously reported at some other API call,so the stacktrace below might be incorrect.
For debugging consider passing CUDA_LAUNCH_BLOCKING=1.
WARNING:torch.distributed.elastic.multiprocessing.api:Sending process 1273 closing signal SIGTERM
ERROR:torch.distributed.elastic.multiprocessing.api:failed (exitcode: 1) local_rank: 1 (pid: 1274) of binary: /home/jovyan/conda-envs/czl/bin/python
Traceback (most recent call last):
  File "/home/jovyan/conda-envs/czl/lib/python3.9/runpy.py", line 197, in _run_module_as_main
    return _run_code(code, main_globals, None,
  File "/home/jovyan/conda-envs/czl/lib/python3.9/runpy.py", line 87, in _run_code
    exec(code, run_globals)
  File "/home/jovyan/conda-envs/czl/lib/python3.9/site-packages/torch/distributed/launch.py", line 193, in <module>
    main()
  File "/home/jovyan/conda-envs/czl/lib/python3.9/site-packages/torch/distributed/launch.py", line 189, in main
    launch(args)
  File "/home/jovyan/conda-envs/czl/lib/python3.9/site-packages/torch/distributed/launch.py", line 174, in launch
    run(args)
  File "/home/jovyan/conda-envs/czl/lib/python3.9/site-packages/torch/distributed/run.py", line 752, in run
    elastic_launch(
  File "/home/jovyan/conda-envs/czl/lib/python3.9/site-packages/torch/distributed/launcher/api.py", line 131, in __call__
    return launch_agent(self._config, self._entrypoint, list(args))
  File "/home/jovyan/conda-envs/czl/lib/python3.9/site-packages/torch/distributed/launcher/api.py", line 245, in launch_agent
    raise ChildFailedError(
torch.distributed.elastic.multiprocessing.errors.ChildFailedError: 
============================================================
main_avst_loc_glo.py FAILED
------------------------------------------------------------
Failures:
[1]:
  time      : 2022-11-04_14:48:53
  host      : jupyter-chenzailong
  rank      : 2 (local_rank: 2)
  exitcode  : 1 (pid: 1275)
  error_file: <N/A>
  traceback : To enable traceback see: https://pytorch.org/docs/stable/elastic/errors.html
[2]:
  time      : 2022-11-04_14:48:53
  host      : jupyter-chenzailong
  rank      : 3 (local_rank: 3)
  exitcode  : 1 (pid: 1276)
  error_file: <N/A>
  traceback : To enable traceback see: https://pytorch.org/docs/stable/elastic/errors.html
------------------------------------------------------------
Root Cause (first observed failure):
[0]:
  time      : 2022-11-04_14:48:53
  host      : jupyter-chenzailong
  rank      : 1 (local_rank: 1)
  exitcode  : 1 (pid: 1274)
  error_file: <N/A>
  traceback : To enable traceback see: https://pytorch.org/docs/stable/elastic/errors.html
============================================================
